Input Notebook:  occ_sim_US_get_cosine_sim_matrix.ipynb
Output Notebook: outputs/occ_sim_US_get_cosine_sim_matrix_out.ipynb
Executing:   0%|                                                                                                                                                          | 0/12 [00:00<?, ?cell/s]Executing notebook with kernel: python3
Executing:   8%|████████████▏                                                                                                                                     | 1/12 [00:04<00:45,  4.13s/cell]Executing:   8%|████████████▏                                                                                                                                     | 1/12 [00:04<00:47,  4.34s/cell]
Traceback (most recent call last):
  File "/users/xiet13/.local/bin/papermill", line 8, in <module>
    sys.exit(papermill())
  File "/opt/apps/hand/anaconda3/202303/lib/python3.10/site-packages/click/core.py", line 1157, in __call__
    return self.main(*args, **kwargs)
  File "/opt/apps/hand/anaconda3/202303/lib/python3.10/site-packages/click/core.py", line 1078, in main
    rv = self.invoke(ctx)
  File "/opt/apps/hand/anaconda3/202303/lib/python3.10/site-packages/click/core.py", line 1434, in invoke
    return ctx.invoke(self.callback, **ctx.params)
  File "/opt/apps/hand/anaconda3/202303/lib/python3.10/site-packages/click/core.py", line 783, in invoke
    return __callback(*args, **kwargs)
  File "/opt/apps/hand/anaconda3/202303/lib/python3.10/site-packages/click/decorators.py", line 33, in new_func
    return f(get_current_context(), *args, **kwargs)
  File "/users/xiet13/.local/lib/python3.10/site-packages/papermill/cli.py", line 250, in papermill
    execute_notebook(
  File "/users/xiet13/.local/lib/python3.10/site-packages/papermill/execute.py", line 128, in execute_notebook
    raise_for_execution_errors(nb, output_path)
  File "/users/xiet13/.local/lib/python3.10/site-packages/papermill/execute.py", line 232, in raise_for_execution_errors
    raise error
papermill.exceptions.PapermillExecutionError: 
---------------------------------------------------------------------------
Exception encountered at "In [1]":
---------------------------------------------------------------------------
ModuleNotFoundError                       Traceback (most recent call last)
Cell In[1], line 1
----> 1 import pandas as pd
      2 import numpy as np
      3 from sklearn.feature_extraction.text import CountVectorizer

ModuleNotFoundError: No module named 'pandas'

